[2025-05-07T21:13:45.478+0000] {taskinstance.py:1956} INFO - Dependencies all met for dep_context=non-requeueable deps ti=<TaskInstance: data_pipeline.download_dataset scheduled__2025-05-06T00:00:00+00:00 [queued]>
[2025-05-07T21:13:45.537+0000] {taskinstance.py:1956} INFO - Dependencies all met for dep_context=requeueable deps ti=<TaskInstance: data_pipeline.download_dataset scheduled__2025-05-06T00:00:00+00:00 [queued]>
[2025-05-07T21:13:45.537+0000] {taskinstance.py:2170} INFO - Starting attempt 2 of 2
[2025-05-07T21:13:45.572+0000] {taskinstance.py:2191} INFO - Executing <Task(PythonOperator): download_dataset> on 2025-05-06 00:00:00+00:00
[2025-05-07T21:13:45.608+0000] {standard_task_runner.py:60} INFO - Started process 480 to run task
[2025-05-07T21:13:45.628+0000] {standard_task_runner.py:87} INFO - Running: ['***', 'tasks', 'run', 'data_pipeline', 'download_dataset', 'scheduled__2025-05-06T00:00:00+00:00', '--job-id', '4', '--raw', '--subdir', 'DAGS_FOLDER/data_pipeline_dag.py', '--cfg-path', '/tmp/tmpgrjmi4oa']
[2025-05-07T21:13:45.639+0000] {standard_task_runner.py:88} INFO - Job 4: Subtask download_dataset
[2025-05-07T21:13:45.888+0000] {task_command.py:423} INFO - Running <TaskInstance: data_pipeline.download_dataset scheduled__2025-05-06T00:00:00+00:00 [running]> on host 48756f42b410
[2025-05-07T21:13:46.179+0000] {taskinstance.py:2480} INFO - Exporting env vars: AIRFLOW_CTX_DAG_OWNER='***' AIRFLOW_CTX_DAG_ID='data_pipeline' AIRFLOW_CTX_TASK_ID='download_dataset' AIRFLOW_CTX_EXECUTION_DATE='2025-05-06T00:00:00+00:00' AIRFLOW_CTX_TRY_NUMBER='2' AIRFLOW_CTX_DAG_RUN_ID='scheduled__2025-05-06T00:00:00+00:00'
[2025-05-07T21:13:46.185+0000] {taskinstance.py:2698} ERROR - Task failed with exception
Traceback (most recent call last):
  File "/home/airflow/.local/lib/python3.8/site-packages/airflow/models/taskinstance.py", line 433, in _execute_task
    result = execute_callable(context=context, **execute_callable_kwargs)
  File "/home/airflow/.local/lib/python3.8/site-packages/airflow/operators/python.py", line 199, in execute
    return_value = self.execute_callable()
  File "/home/airflow/.local/lib/python3.8/site-packages/airflow/operators/python.py", line 216, in execute_callable
    return self.python_callable(*self.op_args, **self.op_kwargs)
  File "/opt/airflow/dags/data_pipeline_dag.py", line 12, in download_dataset
    os.makedirs(data_root, exist_ok=True)
  File "/usr/local/lib/python3.8/os.py", line 223, in makedirs
    mkdir(name, mode)
PermissionError: [Errno 13] Permission denied: '/opt/airflow/datasets/Diabetes'
[2025-05-07T21:13:46.213+0000] {taskinstance.py:1138} INFO - Marking task as FAILED. dag_id=data_pipeline, task_id=download_dataset, execution_date=20250506T000000, start_date=20250507T211345, end_date=20250507T211346
[2025-05-07T21:13:46.257+0000] {standard_task_runner.py:107} ERROR - Failed to execute job 4 for task download_dataset ([Errno 13] Permission denied: '/opt/airflow/datasets/Diabetes'; 480)
[2025-05-07T21:13:46.356+0000] {local_task_job_runner.py:234} INFO - Task exited with return code 1
[2025-05-07T21:13:46.681+0000] {taskinstance.py:3280} INFO - 0 downstream tasks scheduled from follow-on schedule check
