[2025-05-07T21:08:40.905+0000] {taskinstance.py:1956} INFO - Dependencies all met for dep_context=non-requeueable deps ti=<TaskInstance: data_pipeline.download_dataset scheduled__2025-05-06T00:00:00+00:00 [queued]>
[2025-05-07T21:08:41.046+0000] {taskinstance.py:1956} INFO - Dependencies all met for dep_context=requeueable deps ti=<TaskInstance: data_pipeline.download_dataset scheduled__2025-05-06T00:00:00+00:00 [queued]>
[2025-05-07T21:08:41.049+0000] {taskinstance.py:2170} INFO - Starting attempt 1 of 2
[2025-05-07T21:08:41.135+0000] {taskinstance.py:2191} INFO - Executing <Task(PythonOperator): download_dataset> on 2025-05-06 00:00:00+00:00
[2025-05-07T21:08:41.185+0000] {standard_task_runner.py:60} INFO - Started process 329 to run task
[2025-05-07T21:08:41.227+0000] {standard_task_runner.py:87} INFO - Running: ['***', 'tasks', 'run', 'data_pipeline', 'download_dataset', 'scheduled__2025-05-06T00:00:00+00:00', '--job-id', '2', '--raw', '--subdir', 'DAGS_FOLDER/data_pipeline_dag.py', '--cfg-path', '/tmp/tmplrx0jr3c']
[2025-05-07T21:08:41.259+0000] {standard_task_runner.py:88} INFO - Job 2: Subtask download_dataset
[2025-05-07T21:08:41.803+0000] {task_command.py:423} INFO - Running <TaskInstance: data_pipeline.download_dataset scheduled__2025-05-06T00:00:00+00:00 [running]> on host 48756f42b410
[2025-05-07T21:08:42.609+0000] {taskinstance.py:2480} INFO - Exporting env vars: AIRFLOW_CTX_DAG_OWNER='***' AIRFLOW_CTX_DAG_ID='data_pipeline' AIRFLOW_CTX_TASK_ID='download_dataset' AIRFLOW_CTX_EXECUTION_DATE='2025-05-06T00:00:00+00:00' AIRFLOW_CTX_TRY_NUMBER='1' AIRFLOW_CTX_DAG_RUN_ID='scheduled__2025-05-06T00:00:00+00:00'
[2025-05-07T21:08:42.626+0000] {taskinstance.py:2698} ERROR - Task failed with exception
Traceback (most recent call last):
  File "/home/airflow/.local/lib/python3.8/site-packages/airflow/models/taskinstance.py", line 433, in _execute_task
    result = execute_callable(context=context, **execute_callable_kwargs)
  File "/home/airflow/.local/lib/python3.8/site-packages/airflow/operators/python.py", line 199, in execute
    return_value = self.execute_callable()
  File "/home/airflow/.local/lib/python3.8/site-packages/airflow/operators/python.py", line 216, in execute_callable
    return self.python_callable(*self.op_args, **self.op_kwargs)
  File "/opt/airflow/dags/data_pipeline_dag.py", line 12, in download_dataset
    os.makedirs(data_root, exist_ok=True)
  File "/usr/local/lib/python3.8/os.py", line 223, in makedirs
    mkdir(name, mode)
PermissionError: [Errno 13] Permission denied: '/opt/airflow/datasets/Diabetes'
[2025-05-07T21:08:42.718+0000] {taskinstance.py:1138} INFO - Marking task as UP_FOR_RETRY. dag_id=data_pipeline, task_id=download_dataset, execution_date=20250506T000000, start_date=20250507T210840, end_date=20250507T210842
[2025-05-07T21:08:42.767+0000] {standard_task_runner.py:107} ERROR - Failed to execute job 2 for task download_dataset ([Errno 13] Permission denied: '/opt/airflow/datasets/Diabetes'; 329)
[2025-05-07T21:08:42.838+0000] {local_task_job_runner.py:234} INFO - Task exited with return code 1
[2025-05-07T21:08:43.006+0000] {taskinstance.py:3280} INFO - 0 downstream tasks scheduled from follow-on schedule check
