[2025-05-01T13:45:10.474+0000] {taskinstance.py:1956} INFO - Dependencies all met for dep_context=non-requeueable deps ti=<TaskInstance: training_and_selection.train_random_forest scheduled__2025-04-30T00:00:00+00:00 [queued]>
[2025-05-01T13:45:10.490+0000] {taskinstance.py:1956} INFO - Dependencies all met for dep_context=requeueable deps ti=<TaskInstance: training_and_selection.train_random_forest scheduled__2025-04-30T00:00:00+00:00 [queued]>
[2025-05-01T13:45:10.491+0000] {taskinstance.py:2170} INFO - Starting attempt 2 of 2
[2025-05-01T13:45:10.507+0000] {taskinstance.py:2191} INFO - Executing <Task(PythonOperator): train_random_forest> on 2025-04-30 00:00:00+00:00
[2025-05-01T13:45:10.533+0000] {standard_task_runner.py:60} INFO - Started process 352 to run task
[2025-05-01T13:45:10.541+0000] {standard_task_runner.py:87} INFO - Running: ['***', 'tasks', 'run', 'training_and_selection', 'train_random_forest', 'scheduled__2025-04-30T00:00:00+00:00', '--job-id', '31', '--raw', '--subdir', 'DAGS_FOLDER/training_pipeline_dag.py', '--cfg-path', '/tmp/tmp8dv81pu_']
[2025-05-01T13:45:10.546+0000] {standard_task_runner.py:88} INFO - Job 31: Subtask train_random_forest
[2025-05-01T13:45:10.583+0000] {logging_mixin.py:188} WARNING - /home/***/.local/lib/python3.8/site-packages/***/settings.py:194 DeprecationWarning: The sql_alchemy_conn option in [core] has been moved to the sql_alchemy_conn option in [database] - the old setting has been used, but please update your config.
[2025-05-01T13:45:11.035+0000] {task_command.py:423} INFO - Running <TaskInstance: training_and_selection.train_random_forest scheduled__2025-04-30T00:00:00+00:00 [running]> on host 6866968f841d
[2025-05-01T13:45:11.163+0000] {taskinstance.py:2480} INFO - Exporting env vars: AIRFLOW_CTX_DAG_OWNER='***' AIRFLOW_CTX_DAG_ID='training_and_selection' AIRFLOW_CTX_TASK_ID='train_random_forest' AIRFLOW_CTX_EXECUTION_DATE='2025-04-30T00:00:00+00:00' AIRFLOW_CTX_TRY_NUMBER='2' AIRFLOW_CTX_DAG_RUN_ID='scheduled__2025-04-30T00:00:00+00:00'
[2025-05-01T13:45:11.166+0000] {crypto.py:82} WARNING - empty cryptography key - values will not be stored encrypted.
[2025-05-01T13:45:11.167+0000] {base.py:83} INFO - Using connection ID 'postgres_default' for task execution.
[2025-05-01T13:45:16.672+0000] {logging_mixin.py:188} WARNING - 2025/05/01 13:45:16 WARNING mlflow.utils.git_utils: Failed to import Git (the Git executable is probably not on your PATH), so Git SHA is not available. Error: Failed to initialize: Bad git executable.
The git executable must be specified in one of the following ways:
    - be included in your $PATH
    - be set via $GIT_PYTHON_GIT_EXECUTABLE
    - explicitly set via git.refresh(<full-path-to-git-executable>)

All git commands will error until this is rectified.

This initial message can be silenced or aggravated in the future by setting the
$GIT_PYTHON_REFRESH environment variable. Use one of the following values:
    - quiet|q|silence|s|silent|none|n|0: for no message or exception
    - warn|w|warning|log|l|1: for a warning message (logging level CRITICAL, displayed by default)
    - error|e|exception|raise|r|2: for a raised exception

Example:
    export GIT_PYTHON_REFRESH=quiet
[2025-05-01T13:45:17.465+0000] {taskinstance.py:2698} ERROR - Task failed with exception
Traceback (most recent call last):
  File "/home/airflow/.local/lib/python3.8/site-packages/airflow/models/taskinstance.py", line 433, in _execute_task
    result = execute_callable(context=context, **execute_callable_kwargs)
  File "/home/airflow/.local/lib/python3.8/site-packages/airflow/operators/python.py", line 199, in execute
    return_value = self.execute_callable()
  File "/home/airflow/.local/lib/python3.8/site-packages/airflow/operators/python.py", line 216, in execute_callable
    return self.python_callable(*self.op_args, **self.op_kwargs)
  File "/opt/airflow/dags/training_pipeline_dag.py", line 40, in train_random_forest
    model.fit(X_train, y_train)
  File "/home/airflow/.local/lib/python3.8/site-packages/sklearn/base.py", line 1152, in wrapper
    return fit_method(estimator, *args, **kwargs)
  File "/home/airflow/.local/lib/python3.8/site-packages/sklearn/ensemble/_forest.py", line 348, in fit
    X, y = self._validate_data(
  File "/home/airflow/.local/lib/python3.8/site-packages/sklearn/base.py", line 622, in _validate_data
    X, y = check_X_y(X, y, **check_params)
  File "/home/airflow/.local/lib/python3.8/site-packages/sklearn/utils/validation.py", line 1146, in check_X_y
    X = check_array(
  File "/home/airflow/.local/lib/python3.8/site-packages/sklearn/utils/validation.py", line 915, in check_array
    array = _asarray_with_order(array, order=order, dtype=dtype, xp=xp)
  File "/home/airflow/.local/lib/python3.8/site-packages/sklearn/utils/_array_api.py", line 380, in _asarray_with_order
    array = numpy.asarray(array, order=order, dtype=dtype)
  File "/home/airflow/.local/lib/python3.8/site-packages/pandas/core/generic.py", line 1998, in __array__
    arr = np.asarray(values, dtype=dtype)
ValueError: could not convert string to float: 'Caucasian'
[2025-05-01T13:45:17.499+0000] {taskinstance.py:1138} INFO - Marking task as FAILED. dag_id=training_and_selection, task_id=train_random_forest, execution_date=20250430T000000, start_date=20250501T134510, end_date=20250501T134517
[2025-05-01T13:45:17.529+0000] {standard_task_runner.py:107} ERROR - Failed to execute job 31 for task train_random_forest (could not convert string to float: 'Caucasian'; 352)
[2025-05-01T13:45:17.689+0000] {local_task_job_runner.py:234} INFO - Task exited with return code 1
[2025-05-01T13:45:18.009+0000] {taskinstance.py:3280} INFO - 0 downstream tasks scheduled from follow-on schedule check
