[2025-05-01T16:03:35.842+0000] {taskinstance.py:1956} INFO - Dependencies all met for dep_context=non-requeueable deps ti=<TaskInstance: training_and_selection.train_random_forest manual__2025-05-01T15:58:19.368455+00:00 [queued]>
[2025-05-01T16:03:35.862+0000] {taskinstance.py:1956} INFO - Dependencies all met for dep_context=requeueable deps ti=<TaskInstance: training_and_selection.train_random_forest manual__2025-05-01T15:58:19.368455+00:00 [queued]>
[2025-05-01T16:03:35.865+0000] {taskinstance.py:2170} INFO - Starting attempt 2 of 2
[2025-05-01T16:03:36.361+0000] {taskinstance.py:2191} INFO - Executing <Task(PythonOperator): train_random_forest> on 2025-05-01 15:58:19.368455+00:00
[2025-05-01T16:03:36.411+0000] {standard_task_runner.py:60} INFO - Started process 336 to run task
[2025-05-01T16:03:36.436+0000] {standard_task_runner.py:87} INFO - Running: ['***', 'tasks', 'run', 'training_and_selection', 'train_random_forest', 'manual__2025-05-01T15:58:19.368455+00:00', '--job-id', '70', '--raw', '--subdir', 'DAGS_FOLDER/training_pipeline_dag.py', '--cfg-path', '/tmp/tmpxi6jpu1j']
[2025-05-01T16:03:36.438+0000] {standard_task_runner.py:88} INFO - Job 70: Subtask train_random_forest
[2025-05-01T16:03:36.528+0000] {logging_mixin.py:188} WARNING - /home/***/.local/lib/python3.8/site-packages/***/settings.py:194 DeprecationWarning: The sql_alchemy_conn option in [core] has been moved to the sql_alchemy_conn option in [database] - the old setting has been used, but please update your config.
[2025-05-01T16:03:36.693+0000] {task_command.py:423} INFO - Running <TaskInstance: training_and_selection.train_random_forest manual__2025-05-01T15:58:19.368455+00:00 [running]> on host d44e3d946aba
[2025-05-01T16:03:36.948+0000] {taskinstance.py:2480} INFO - Exporting env vars: AIRFLOW_CTX_DAG_OWNER='***' AIRFLOW_CTX_DAG_ID='training_and_selection' AIRFLOW_CTX_TASK_ID='train_random_forest' AIRFLOW_CTX_EXECUTION_DATE='2025-05-01T15:58:19.368455+00:00' AIRFLOW_CTX_TRY_NUMBER='2' AIRFLOW_CTX_DAG_RUN_ID='manual__2025-05-01T15:58:19.368455+00:00'
[2025-05-01T16:03:36.965+0000] {crypto.py:82} WARNING - empty cryptography key - values will not be stored encrypted.
[2025-05-01T16:03:36.966+0000] {base.py:83} INFO - Using connection ID 'postgres_default' for task execution.
[2025-05-01T16:03:39.915+0000] {logging_mixin.py:188} WARNING - 2025/05/01 16:03:39 WARNING mlflow.utils.git_utils: Failed to import Git (the Git executable is probably not on your PATH), so Git SHA is not available. Error: Failed to initialize: Bad git executable.
The git executable must be specified in one of the following ways:
    - be included in your $PATH
    - be set via $GIT_PYTHON_GIT_EXECUTABLE
    - explicitly set via git.refresh(<full-path-to-git-executable>)

All git commands will error until this is rectified.

This initial message can be silenced or aggravated in the future by setting the
$GIT_PYTHON_REFRESH environment variable. Use one of the following values:
    - quiet|q|silence|s|silent|none|n|0: for no message or exception
    - warn|w|warning|log|l|1: for a warning message (logging level CRITICAL, displayed by default)
    - error|e|exception|raise|r|2: for a raised exception

Example:
    export GIT_PYTHON_REFRESH=quiet
[2025-05-01T16:03:40.086+0000] {logging_mixin.py:188} WARNING - 2025/05/01 16:03:40 INFO mlflow.tracking._tracking_service.client: üèÉ View run RandomForest at: http://mlflow:5000/#/experiments/225220923780667378/runs/0de9787c6bbe420f961b74a5f531806b.
[2025-05-01T16:03:40.092+0000] {logging_mixin.py:188} WARNING - 2025/05/01 16:03:40 INFO mlflow.tracking._tracking_service.client: üß™ View experiment at: http://mlflow:5000/#/experiments/225220923780667378.
[2025-05-01T16:03:40.130+0000] {taskinstance.py:2698} ERROR - Task failed with exception
Traceback (most recent call last):
  File "/home/airflow/.local/lib/python3.8/site-packages/pandas/core/indexes/base.py", line 3653, in get_loc
    return self._engine.get_loc(casted_key)
  File "pandas/_libs/index.pyx", line 147, in pandas._libs.index.IndexEngine.get_loc
  File "pandas/_libs/index.pyx", line 176, in pandas._libs.index.IndexEngine.get_loc
  File "pandas/_libs/hashtable_class_helper.pxi", line 7080, in pandas._libs.hashtable.PyObjectHashTable.get_item
  File "pandas/_libs/hashtable_class_helper.pxi", line 7088, in pandas._libs.hashtable.PyObjectHashTable.get_item
KeyError: 'race'

The above exception was the direct cause of the following exception:

Traceback (most recent call last):
  File "/home/airflow/.local/lib/python3.8/site-packages/sklearn/utils/__init__.py", line 447, in _get_column_indices
    col_idx = all_columns.get_loc(col)
  File "/home/airflow/.local/lib/python3.8/site-packages/pandas/core/indexes/base.py", line 3655, in get_loc
    raise KeyError(key) from err
KeyError: 'race'

The above exception was the direct cause of the following exception:

Traceback (most recent call last):
  File "/home/airflow/.local/lib/python3.8/site-packages/airflow/models/taskinstance.py", line 433, in _execute_task
    result = execute_callable(context=context, **execute_callable_kwargs)
  File "/home/airflow/.local/lib/python3.8/site-packages/airflow/operators/python.py", line 199, in execute
    return_value = self.execute_callable()
  File "/home/airflow/.local/lib/python3.8/site-packages/airflow/operators/python.py", line 216, in execute_callable
    return self.python_callable(*self.op_args, **self.op_kwargs)
  File "/opt/airflow/dags/training_pipeline_dag.py", line 89, in train_random_forest
    _train_model(
  File "/opt/airflow/dags/training_pipeline_dag.py", line 77, in _train_model
    pipeline.fit(X_train, y_train)
  File "/home/airflow/.local/lib/python3.8/site-packages/sklearn/base.py", line 1152, in wrapper
    return fit_method(estimator, *args, **kwargs)
  File "/home/airflow/.local/lib/python3.8/site-packages/sklearn/pipeline.py", line 423, in fit
    Xt = self._fit(X, y, **fit_params_steps)
  File "/home/airflow/.local/lib/python3.8/site-packages/sklearn/pipeline.py", line 377, in _fit
    X, fitted_transformer = fit_transform_one_cached(
  File "/home/airflow/.local/lib/python3.8/site-packages/joblib/memory.py", line 312, in __call__
    return self.func(*args, **kwargs)
  File "/home/airflow/.local/lib/python3.8/site-packages/sklearn/pipeline.py", line 957, in _fit_transform_one
    res = transformer.fit_transform(X, y, **fit_params)
  File "/home/airflow/.local/lib/python3.8/site-packages/sklearn/utils/_set_output.py", line 157, in wrapped
    data_to_wrap = f(self, X, *args, **kwargs)
  File "/home/airflow/.local/lib/python3.8/site-packages/sklearn/base.py", line 1152, in wrapper
    return fit_method(estimator, *args, **kwargs)
  File "/home/airflow/.local/lib/python3.8/site-packages/sklearn/compose/_column_transformer.py", line 751, in fit_transform
    self._validate_column_callables(X)
  File "/home/airflow/.local/lib/python3.8/site-packages/sklearn/compose/_column_transformer.py", line 459, in _validate_column_callables
    transformer_to_input_indices[name] = _get_column_indices(X, columns)
  File "/home/airflow/.local/lib/python3.8/site-packages/sklearn/utils/__init__.py", line 455, in _get_column_indices
    raise ValueError("A given column is not a column of the dataframe") from e
ValueError: A given column is not a column of the dataframe
[2025-05-01T16:03:40.197+0000] {taskinstance.py:1138} INFO - Marking task as FAILED. dag_id=training_and_selection, task_id=train_random_forest, execution_date=20250501T155819, start_date=20250501T160335, end_date=20250501T160340
[2025-05-01T16:03:40.240+0000] {standard_task_runner.py:107} ERROR - Failed to execute job 70 for task train_random_forest (A given column is not a column of the dataframe; 336)
[2025-05-01T16:03:40.343+0000] {local_task_job_runner.py:234} INFO - Task exited with return code 1
[2025-05-01T16:03:40.405+0000] {taskinstance.py:3280} INFO - 0 downstream tasks scheduled from follow-on schedule check
